<?xml version="1.0" ?>

<!--Name of the robot: mykuka-->
<robot name="mykuka">
    <!--First link: the base_link-->
    <link name="base_link">
        <!--Grahical shape -->
        <visual>
            <geometry>
                <cylinder length="0.1" radius="0.2"/>
            </geometry>
            <origin rpy="0 0 0" xyz="0 0 0"/>
            <material name="grey">
                <color rgba="0.75 0.75 0.75 1"/>
            </material>
        </visual>
        <!--Physical shape -->
        <collision>
            <geometry>
                <cylinder length="0.1" radius="0.2"/>
            </geometry>
            <origin rpy="0 0 0" xyz="0 0 0"/>
        </collision>
    </link>

    <!--Joint connecting the base_link with the link1-->
    <joint name="joint1" type="revolute">
        <parent link="base_link"/>
        <child link="link1"/>
        <origin xyz="0 0 0.1"/>
        <axis xyz="0 0 1" />
        <limit effort="300" velocity="0.1" lower="-1.57" upper="1.57"/>
    </joint>

    <link name="link1">
        <visual>
            <geometry>
                <cylinder length="0.4" radius="0.07"/>
            </geometry>
            <origin rpy="0 0 0" xyz="0 0 0.09"/>
            <material name="blue">
                <color rgba="0.94 0.36 0.09 1"/>
            </material>
        </visual>
        <collision>
            <geometry>
                <cylinder length="0.4" radius="0.07"/>
            </geometry>
            <origin rpy="0 0 0" xyz="0 0 0.09"/>
        </collision>
        <inertial>
            <mass value="1"/>
            <inertia ixx="1.0" ixy="0.0" ixz="0.0" iyy="1.0" iyz="0.0" izz="1.0"/>
        </inertial>
    </link>

    <joint name="joint2" type="revolute">
        <parent link="link1"/>
        <child link="link2"/>
        <origin xyz="0 0 0.3"/>
        <axis xyz="1 0 0" />
        <limit effort="300" velocity="0.1" lower="-1.5" upper="1.5"/>
    </joint>

    <link name="link2">
        <visual>
            <geometry>
                <cylinder length="0.2" radius="0.07"/>
            </geometry>
            <origin rpy="0 1.57 0" xyz="0.1 0 0"/>
            <material name="red">
                <color rgba="0.94 0.36 0.09 1"/>
            </material>
        </visual>
        <collision>
            <geometry>
                <cylinder length="0.2" radius="0.07"/>
            </geometry>
            <origin rpy="0 1.5 0" xyz="0.1 0 0"/>
        </collision>
        <inertial>
            <mass value="1"/>
            <inertia ixx="1.0" ixy="0.0" ixz="0.0" iyy="1.0" iyz="0.0" izz="1.0"/>
        </inertial>
    </link>

    <joint name="joint3" type="revolute">
        <parent link="link2"/>
        <child link="link3"/>
        <origin xyz="0.2 0 0"/>
        <axis xyz="0 0 1" />
        <limit effort="300" velocity="0.1" lower="-1.57" upper="1.57"/>
    </joint>

    <link name="link3">
        <visual>
            <geometry>
                <cylinder length="0.4" radius="0.07"/>
            </geometry>
            <origin rpy="0 0 0" xyz="0 0 0.17"/>
            <material name="red">
                <color rgba="0.94 0.36 0.09 1"/>
            </material>
        </visual>
        <collision>
            <geometry>
                <cylinder length="0.4" radius="0.07"/>
            </geometry>
            <origin rpy="0 0 0" xyz="0 0 0.17"/>
        </collision>
        <inertial>
            <mass value="1"/>
            <inertia ixx="1.0" ixy="0.0" ixz="0.0" iyy="1.0" iyz="0.0" izz="1.0"/>
        </inertial>
    </link>

    <joint name="joint4" type="revolute">
        <parent link="link3"/>
        <child link="link4"/>
        <origin xyz="0 0 0.4"/>
        <axis xyz="1 0 0" />
        <limit effort="300" velocity="0.1" lower="-1.57" upper="1.57"/>
    </joint>

    <link name="link4">
        <visual>
            <geometry>
                <cylinder length="0.2" radius="0.07"/>
            </geometry>
            <origin rpy="0 1.57 0" xyz="-0.1 0 0"/>
            <material name="red">
                <color rgba="0.94 0.36 0.09 1"/>
            </material>
        </visual>
        <collision>
            <geometry>
                <cylinder length="0.2" radius="0.07"/>
            </geometry>
            <origin rpy="0 1.57 0" xyz="-0.1 0 0"/>
        </collision>
        <inertial>
            <mass value="1"/>
            <inertia ixx="1.0" ixy="0.0" ixz="0.0" iyy="1.0" iyz="0.0" izz="1.0"/>
        </inertial>
	</link>

    <joint name="joint5" type="revolute">
        <parent link="link4"/>
        <child link="link5"/>
        <origin xyz="-0.2 0 0.1"/>
        <axis xyz="0 0 1" />
        <limit effort="300" velocity="0.1" lower="-3.14" upper="3.14"/>
    </joint>

    <link name="link5">
        <visual>
            <geometry>
                <cylinder length="0.4" radius="0.07"/>
            </geometry>
            <origin rpy="0 0 0" xyz="0 0 0.09"/>
            <material name="blue">
                <color rgba="0.94 0.36 0.09 1"/>
            </material>
        </visual>
        <collision>
            <geometry>
                <cylinder length="0.4" radius="0.07"/>
            </geometry>
            <origin rpy="0 0 0" xyz="0 0 0.09"/>
        </collision>
        <inertial>
            <mass value="1"/>
            <inertia ixx="1.0" ixy="0.0" ixz="0.0" iyy="1.0" iyz="0.0" izz="1.0"/>
        </inertial>
    </link>

    <joint name="joint6" type="revolute">
        <parent link="link5"/>
        <child link="link6"/>
        <origin xyz="0 0 0.3"/>
        <axis xyz="1 0 0" />
        <limit effort="300" velocity="0.1" lower="-1.5" upper="1.5"/>
    </joint>

    <link name="link6">
        <visual>
            <geometry>
                <cylinder length="0.2" radius="0.07"/>
            </geometry>
            <origin rpy="0 1.57 0" xyz="0.1 0 0"/>
            <material name="red">
                <color rgba="0.94 0.36 0.09 1"/>
            </material>
        </visual>
        <collision>
            <geometry>
                <cylinder length="0.2" radius="0.07"/>
            </geometry>
            <origin rpy="0 1.5 0" xyz="0.1 0 0"/>
        </collision>
        <inertial>
            <mass value="1"/>
            <inertia ixx="1.0" ixy="0.0" ixz="0.0" iyy="1.0" iyz="0.0" izz="1.0"/>
        </inertial>
    </link>

    <joint name="joint7" type="revolute">
        <parent link="link6"/>
        <child link="link7"/>
        <origin xyz="0.2 0 0"/>
        <axis xyz="0 0 1" />
        <limit effort="300" velocity="0.1" lower="-1.57" upper="1.57"/>
    </joint>

    <link name="link7">
        <visual>
            <geometry>
                <cylinder length="0.4" radius="0.07"/>
            </geometry>
            <origin rpy="0 0 0" xyz="0 0 0.17"/>
            <material name="red">
                <color rgba="0.94 0.36 0.09 1"/>
            </material>
        </visual>
        <collision>
            <geometry>
                <cylinder length="0.4" radius="0.07"/>
            </geometry>
            <origin rpy="0 0 0" xyz="0 0 0.17"/>
        </collision>
        <inertial>
            <mass value="1"/>
            <inertia ixx="1.0" ixy="0.0" ixz="0.0" iyy="1.0" iyz="0.0" izz="1.0"/>
        </inertial>
    </link>

</robot>
